{
  "error_type": "RuntimeError",
  "message": "Traceback (most recent call last):\n  File \"/home/wan00559/cuda_mind_evolution/scripts/compile_and_run.py\", line 213, in compare_and_bench\n    test_out, _ = _run_once(ModelNew(), inp, dev)\n                  ^^^^^^^^^^^^^^^^^^^^^^^^^^^^^^^\n  File \"/home/wan00559/cuda_mind_evolution/scripts/compile_and_run.py\", line 127, in _run_once\n    out = model(*inp)\n          ^^^^^^^^^^^\n  File \"/home/wan00559/miniconda3/envs/maxk/lib/python3.11/site-packages/torch/nn/modules/module.py\", line 1751, in _wrapped_call_impl\n    return self._call_impl(*args, **kwargs)\n           ^^^^^^^^^^^^^^^^^^^^^^^^^^^^^^^^\n  File \"/home/wan00559/miniconda3/envs/maxk/lib/python3.11/site-packages/torch/nn/modules/module.py\", line 1762, in _call_impl\n    return forward_call(*args, **kwargs)\n           ^^^^^^^^^^^^^^^^^^^^^^^^^^^^^\n  File \"/home/wan00559/cuda_mind_evolution/runs/20250805_171039/kernels/kernel_20250805_234605.py\", line 102, in forward\n    return self.matmul_custom(A, B)\n           ^^^^^^^^^^^^^^^^^^^^^^^^\nTypeError: 'module' object is not callable\n"
}